#VRML_SIM R2025a utf8
EXTERNPROTO "https://raw.githubusercontent.com/cyberbotics/webots/R2025a/projects/objects/backgrounds/protos/TexturedBackground.proto"
EXTERNPROTO "https://raw.githubusercontent.com/cyberbotics/webots/R2025a/projects/objects/backgrounds/protos/TexturedBackgroundLight.proto"
EXTERNPROTO "https://raw.githubusercontent.com/cyberbotics/webots/R2025a/projects/objects/floors/protos/RectangleArena.proto"
EXTERNPROTO "https://raw.githubusercontent.com/cyberbotics/webots/R2025a/projects/objects/apartment_structure/protos/Wall.proto"
WorldInfo {
}
Viewpoint {
  orientation -0.5773502691896257 0.5773502691896257 0.5773502691896257 2.0944
  position 0 0 10
}
TexturedBackground {
}
TexturedBackgroundLight {
}
RectangleArena {
}
Robot {
  translation -0.3 0 0.05
  children [
    Shape {
      geometry Box {
        size 0.1 0.1 0.05
      }
    }
    DistanceSensor {
      translation 0.05 0 0
      rotation 0 1 0 0
      name "sonar"
      type "sonar"
      numberOfRays 5
      aperture 0.5
    }
    HingeJoint {
      jointParameters HingeJointParameters {
        axis 0 1 0
        anchor 0 0.06 0
      }
      device [
        RotationalMotor {
          name "left wheel motor"
          maxVelocity 10
        }
      ]
      endPoint Solid {
        translation 0 0.06 0
        name "left wheel"
        children [
          Shape {
            geometry Cylinder {
              height 0.02
              radius 0.03
            }
          }
        ]
        boundingObject Cylinder {
          height 0.02
          radius 0.03
        }
        physics Physics {
        }
      }
    }
    HingeJoint {
      jointParameters HingeJointParameters {
        axis 0 1 0
        anchor 0 -0.06 0
      }
      device [
        RotationalMotor {
          name "right wheel motor"
          maxVelocity 10
        }
      ]
      endPoint Solid {
        translation 0 -0.06 0
        name "right wheel"
        children [
          Shape {
            geometry Cylinder {
              height 0.02
              radius 0.03
            }
          }
        ]
        boundingObject Cylinder {
          height 0.02
          radius 0.03
        }
        physics Physics {
        }
      }
    }
  ]
  boundingObject Box {
    size 0.1 0.1 0.05
  }
  physics Physics {
  }
  controller "distance_sonar"
}
Wall {
  translation 0.3 0 0
  size 0.1 0.5 0.2
}